<?xml version="1.0"?>
<robot xmlns:xacro="http://www.ros.org/wiki/xacro"  name="robot">


<xacro:include filename="inertial_macros.xacro"/>



   <material name="white">
        <color rgba="1 1 1 1" />
    </material>

    <material name="orange">
        <color rgba="1 0.3 0.1 1" />
    </material>

    <material name="blue">
        <color rgba="0.2 0.2 1 1"/>
    </material>

    <material name="black">
        <color rgba="0 0 0 1" />
    </material>

<!--BASE LINK-->
    <link name="base_link">
    </link>
<!--CHASIS LINK-->
<joint name="chasis_joint" type="fixed">
    <parent link="base_link"/>
    <child link="chasis"/>
    <origin xyz="-0.1 0 0"/>
</joint>

    <link name="chasis">
        <visual>
            <origin xyz="0.08 0 0.03"/>
            <geometry>
               <box size="0.16 0.16 0.06"/>
            </geometry>
            <material name="white"/>
        </visual>
        <collision>
            <origin xyz="0.08 0 0.03"/>
            <geometry>
               <box size="0.16 0.16 0.06"/>
            </geometry>
        </collision>
        <xacro:inertial_box mass="1.2" x="0.16" y="0.3" z="0.15">
        <origin xyz="0.08 0 0.03" rpy="0 0 0"/>
        </xacro:inertial_box>
    </link>
<gazebo reference="chasis">
    <material>Gazebo/White</material>
</gazebo>
<!--LEFT WHEEL LINK-->


<joint name="left_wheel_joint" type="continuous"> <!-- continuous means it can rotate feeely unlike fixed link-->
    <parent link="base_link"/>
    <child  link="left_wheel"/>
    <origin xyz="-0.045 0.09 0" rpy="-${pi/2} 0 0"/>
    <axis xyz="0 0 1"/>

</joint>

<link name="left_wheel">
    <visual>
        <geometry>
            <cylinder radius="0.03" length="0.02" />
        </geometry>
        <material name="blue"/>
    </visual>
        <collision>
        <geometry>
            <cylinder radius="0.03" length="0.02" />
        </geometry>
    </collision>
    <xacro:inertial_cylinder mass="0.06" length="0.02" radius="0.03">
    <origin xyz ="0 0 0" rpy="0 0 0"/>
    </xacro:inertial_cylinder>
</link>
<gazebo reference="left_wheel">
    <material>Gazebo/Blue</material>
</gazebo>
<!--RIGHT WHEEL LINK-->


<joint name="right_wheel_joint" type="continuous"> <!-- continuous means it can rotate feeely unlike fixed link-->
    <parent link="base_link"/>
    <child  link="right_wheel"/>
    <origin xyz="-0.045 -0.09 0" rpy="${pi/2} 0 0"/>
    <axis xyz="0 0 -1"/>

</joint>

<link name="right_wheel">
    <visual>
        <geometry>
            <cylinder radius="0.03" length="0.02" />
        </geometry>
        <material name="blue"/>
    </visual>
        <collision>
        <geometry>
            <cylinder radius="0.03" length="0.02" />
        </geometry>
    </collision>
        <xacro:inertial_cylinder mass="0.06" length="0.02" radius="0.03">
    <origin xyz ="0 0 0" rpy="0 0 0"/>
    </xacro:inertial_cylinder>
</link>
<gazebo reference="right_wheel">
    <material>Gazebo/Blue</material>
</gazebo>
<!--CASTOR WHEEL LINK-->

<joint name="castor_wheel_joint" type="fixed">
    <parent link="chasis"/>
    <child link="castor_wheel"/>
    <origin xyz="0.12 0 0"/>
</joint>

 <link name="castor_wheel">
    <visual>
        <geometry>
            <sphere radius="0.03"/>
        </geometry>
        <material name="black"/>
    </visual>
        <collision>
        <geometry>
            <sphere radius="0.03"/>
        </geometry>
    </collision>
    <xacro:inertial_sphere mass="0.08" radius="0.03">
    <origin xyz ="0 0 0" rpy="0 0 0"/>
    </xacro:inertial_sphere>

</link>

<gazebo reference="castor_wheel">
    <material>Gazebo/Black</material>
    <mu1 value="0.0015"/>
    <mu2 value="0.0015"/>
    </gazebo>
</robot>